<robot name="vx300s">
    <link name="base_link">
        <visual>
        <origin rpy="0 0 1.5708" xyz="0 0 0"/>
        <geometry>
            <mesh filename="package:///vx300s_1_base.stl" scale="0.001 0.001 0.001"/>
        </geometry>
        <material name="interbotix_black"/>
        </visual>
        <collision>
        <origin rpy="0 0 1.5708" xyz="0 0 0"/>
        <geometry>
            <mesh filename="package:///vx300s_1_base.stl" scale="0.001 0.001 0.001"/>
        </geometry>
        </collision>
        <inertial>
        <origin rpy="0 0 1.5708" xyz="-0.0534774000 -0.0005625750 0.0205961000"/>
        <mass value="0.969034" />
        <inertia ixx="0.0060240000" iyy="0.0017000000" izz="0.0071620000" ixy="0.0000471300" ixz="0.0000038510" iyz="-0.0000841500" />
        </inertial>
    </link>

    <joint name="waist" type="revolute">
        <axis xyz="0 0 1"/>
        <limit effort="10" lower="-3.14158" upper="3.14158" velocity="3.14159"/>
        <origin rpy="0 0 0" xyz="0 0 0.079"/>
        <parent link="base_link"/>
        <child link="shoulder_link"/>
        <dynamics friction="0.1"/>
    </joint>

    <link name="shoulder_link">
        <visual>
        <origin rpy="0 0 1.5708" xyz="0 0 -0.003"/>
        <geometry>
            <mesh filename="package:///vx300s_2_shoulder.stl" scale="0.001 0.001 0.001"/>
        </geometry>
        <material name="interbotix_black"/>
        </visual>
        <collision>
        <origin rpy="0 0 1.5708" xyz="0 0 -0.003"/>
        <geometry>
            <mesh filename="package:///vx300s_2_shoulder.stl" scale="0.001 0.001 0.001"/>
        </geometry>
        </collision>
        <inertial>
        <origin rpy="0 0 1.5708" xyz="0.0002592330 -0.0000033552 0.0116129000"/>
        <mass value="0.798614" />
        <inertia ixx="0.0009388000" iyy="0.0011380000" izz="0.0012010000" ixy="-0.0000000010" ixz="-0.0000000191" iyz="0.0000059568" />
        </inertial>
    </link>

    <joint name="shoulder" type="revolute">
        <axis xyz="0 1 0"/>
        <limit effort="20" lower="-1.85005" upper="1.25664" velocity="3.14159"/>
        <origin rpy="0 0 0" xyz="0 0 0.04805"/>
        <parent link="shoulder_link"/>
        <child link="upper_arm_link"/>
        <dynamics friction="0.1"/>
    </joint>

    <link name="upper_arm_link">
        <visual>
        <origin rpy="0 0 1.5708" xyz="0 0 0"/>
        <geometry>
            <mesh filename="package:///vx300s_3_upper_arm.stl" scale="0.001 0.001 0.001"/>
        </geometry>
        <material name="interbotix_black"/>
        </visual>
        <collision>
        <origin rpy="0 0 1.5708" xyz="0 0 0"/>
        <geometry>
            <mesh filename="package:///vx300s_3_upper_arm.stl" scale="0.001 0.001 0.001"/>
        </geometry>
        </collision>
        <inertial>
        <origin rpy="0 0 1.5708" xyz="0.0206949000 0.0000000004 0.2264590000"/>
        <mass value="0.792592" />
        <inertia ixx="0.0089250000" iyy="0.0089370000" izz="0.0009357000" ixy="0.0000000000" ixz="0.0000000000" iyz="0.0012010000" />
        </inertial>
    </link>

    <joint name="elbow" type="revolute">
        <axis xyz="0 1 0"/>
        <limit effort="15" lower="-1.76278" upper="1.06057" velocity="3.14159"/>
        <origin rpy="0 0 0" xyz="0.05955 0 0.3"/>
        <parent link="upper_arm_link"/>
        <child link="upper_forearm_link"/>
        <dynamics friction="0.1"/>
    </joint>

    <link name="upper_forearm_link">
        <visual>
        <origin rpy="0 0 0" xyz="0 0 0"/>
        <geometry>
            <mesh filename="package:///vx300s_4_upper_forearm.stl" scale="0.001 0.001 0.001"/>
        </geometry>
        <material name="interbotix_black"/>
        </visual>
        <collision>
        <origin rpy="0 0 0" xyz="0 0 0"/>
        <geometry>
            <mesh filename="package:///vx300s_4_upper_forearm.stl" scale="0.001 0.001 0.001"/>
        </geometry>
        </collision>
        <inertial>
        <origin rpy="0 0 0" xyz="0.105723 0 0"/>
        <mass value="0.322228" />
        <inertia ixx="0.0001524000" iyy="0.0013420000" izz="0.0014410000" ixy="-0.0000188300" ixz="-0.0000084064" iyz="0.0000012564" />
        </inertial>
    </link>

    <joint name="forearm_roll" type="revolute">
        <axis xyz="1 0 0"/>
        <limit effort="2" lower="-3.14158" upper="3.14158" velocity="3.14159"/>
        <origin rpy="0 0 0" xyz="0.2 0 0"/>
        <parent link="upper_forearm_link"/>
        <child link="lower_forearm_link"/>
        <dynamics friction="0.1"/>
    </joint>

    <link name="lower_forearm_link">
        <visual>
        <origin rpy="3.1416 0 0" xyz="0 0 0"/>
        <geometry>
            <mesh filename="package:///vx300s_5_lower_forearm.stl" scale="0.001 0.001 0.001"/>
        </geometry>
        <material name="interbotix_black"/>
        </visual>
        <collision>
        <origin rpy="3.1416 0 0" xyz="0 0 0"/>
        <geometry>
            <mesh filename="package:///vx300s_5_lower_forearm.stl" scale="0.001 0.001 0.001"/>
        </geometry>
        </collision>
        <inertial>
        <origin rpy="3.1416 0 0" xyz="0.0513477000 0.0068046200 0"/>
        <mass value="0.414823" />
        <inertia ixx="0.0001753000" iyy="0.0005269000" izz="0.0005911000" ixy="-0.0000852800" ixz="0" iyz="0" />
        </inertial>
    </link>

    <joint name="wrist_angle" type="revolute">
        <axis xyz="0 1 0"/>
        <limit effort="5" lower="-1.8675" upper="2.23402" velocity="3.14159"/>
        <origin rpy="0 0 0" xyz="0.1 0 0"/>
        <parent link="lower_forearm_link"/>
        <child link="wrist_link"/>
        <dynamics friction="0.1"/>
    </joint>

    <link name="wrist_link">
        <visual>
        <origin rpy="0 0 1.5708" xyz="0 0 0"/>
        <geometry>
            <mesh filename="package:///vx300s_6_wrist.stl" scale="0.001 0.001 0.001"/>
        </geometry>
        <material name="interbotix_black"/>
        </visual>
        <collision>
        <origin rpy="0 0 1.5708" xyz="0 0 0"/>
        <geometry>
            <mesh filename="package:///vx300s_6_wrist.stl" scale="0.001 0.001 0.001"/>
        </geometry>
        </collision>
        <inertial>
        <origin rpy="0 0 1.5708" xyz="0.0467430000 -0.0000076652 0.0105650000"/>
        <mass value="0.115395" />
        <inertia ixx="0.0000463100" iyy="0.0000451400" izz="0.0000527000" ixy="0.0000000195" ixz="0.0000000023" iyz="0.0000042002" />
        </inertial>
    </link>

    <joint name="wrist_rotate" type="revolute">
        <axis xyz="1 0 0"/>
        <limit effort="1" lower="-3.14158" upper="3.14158" velocity="3.14159"/>
        <origin rpy="0 0 0" xyz="0.069744 0 0"/>
        <parent link="wrist_link"/>
        <child link="gripper_link"/>
        <dynamics friction="0.1"/>
    </joint>

    <link name="gripper_link">
        <visual>
        <origin rpy="0 0 1.5708" xyz="-0.02 0 0"/>
        <geometry>
            <mesh filename="package:///vx300s_7_gripper.stl" scale="0.001 0.001 0.001"/>
        </geometry>
        <material name="interbotix_black"/>
        </visual>
        <collision>
        <origin rpy="0 0 1.5708" xyz="-0.02 0 0"/>
        <geometry>
            <mesh filename="package:///vx300s_7_gripper.stl" scale="0.001 0.001 0.001"/>
        </geometry>
        </collision>
        <inertial>
        <origin rpy="0 0 1.5708" xyz="0.0230010000 0.0000000000 0.0115230000"/>
        <mass value="0.097666" />
        <inertia ixx="0.0000326800" iyy="0.0000243600" izz="0.0000211900" ixy="0.0000000000" ixz="0.0000000000" iyz="0.0000002785" />
        </inertial>
    </link>

    <joint name="ee_arm" type="fixed">
        <axis xyz="1 0 0"/>
        <origin rpy="0 0 0" xyz="0.042825 0 0"/>
        <parent link="gripper_link"/>
        <child link="ee_arm_link"/>
    </joint>

    <link name="ee_arm_link">
        <inertial>
        <mass value="0.001" />
        <inertia ixx="0.0001" iyy="0.0001" izz="0.0001" ixy="0" ixz="0" iyz="0" />
        </inertial>
    </link>

    <joint name="gripper" type="continuous">
        <axis xyz="1 0 0"/>
        <limit effort="1" velocity="3.14159"/>
        <origin rpy="0 0 0" xyz="0.005675 0 0"/>
        <parent link="ee_arm_link"/>
        <child link="gripper_prop_link"/>
        <dynamics friction="0.1"/>
    </joint>

    <link name="gripper_prop_link">
        <visual>
        <origin rpy="0 0 1.5708" xyz="-0.0685 0 0"/>
        <geometry>
            <mesh filename="package:///vx300s_8_gripper_prop.stl" scale="0.001 0.001 0.001"/>
        </geometry>
        <material name="interbotix_black"/>
        </visual>
        <collision>
        <origin rpy="0 0 1.5708" xyz="-0.0685 0 0"/>
        <geometry>
            <mesh filename="package:///vx300s_8_gripper_prop.stl" scale="0.001 0.001 0.001"/>
        </geometry>
        </collision>
        <inertial>
        <origin rpy="0 0 1.5708" xyz="0.0023780000 0.0000000285 0.0000000000"/>
        <mass value="0.008009" />
        <inertia ixx="0.0000020386" iyy="0.0000042979" izz="0.0000023796" ixy="0.0000000000" ixz="0.0000006559" iyz="0.0000000000" />
        </inertial>
    </link>

    <joint name="ar_tag" type="fixed">
      <axis xyz="0 0 0"/>
      <origin rpy="0 0 0" xyz="-0.017 0 0.04155"/>
      <parent link="ee_arm_link"/>
      <child link="ar_tag_link"/>
    </joint>

    <link name="ar_tag_link">
      <visual>
        <origin rpy="0 0 0" xyz="0 0 0"/>
        <geometry>
          <mesh filename="package:///vx300s_11_ar_tag.stl" scale="0.001 0.001 0.001"/>
        </geometry>
        <material name="interbotix_black"/>
      </visual>
      <collision>
        <origin rpy="0 0 0" xyz="0 0 0"/>
        <geometry>
          <mesh filename="package:///vx300s_11_ar_tag.stl" scale="0.001 0.001 0.001"/>
        </geometry>
      </collision>
      <inertial>
        <origin rpy="0 0 0" xyz="0 0 -0.00315"/>
        <mass value="0.016507"/>
        <inertia ixx="0.000003084" ixy="0" ixz="0" iyy="0.000003084" iyz="0" izz="0.000006059"/>
      </inertial>
    </link>

    <joint name="gripper_bar" type="fixed">
      <axis xyz="1 0 0"/>
      <origin rpy="0 0 0" xyz="0 0 0"/>
      <parent link="ee_arm_link"/>
      <child link="gripper_bar_link"/>
    </joint>

    <link name="gripper_bar_link">
      <visual>
        <origin rpy="0 0 1.5708" xyz="-0.063 0 0"/>
        <geometry>
          <mesh filename="package:///vx300s_9_gripper_bar.stl" scale="0.001 0.001 0.001"/>
        </geometry>
        <material name="interbotix_black"/>
      </visual>
      <collision>
        <origin rpy="0 0 1.5708" xyz="-0.063 0 0"/>
        <geometry>
          <mesh filename="package:///vx300s_9_gripper_bar.stl" scale="0.001 0.001 0.001"/>
        </geometry>
      </collision>
      <inertial>
        <origin rpy="0 0 1.5708" xyz="0.0067940000 -0.0000004272 -0.0007760000"/>
        <mass value="0.150986" />
        <inertia ixx="0.0000789500" iyy="0.0003283000" izz="0.0003095000" ixy="-0.0000000012" ixz="0.0000001341" iyz="0.0000017465" />
      </inertial>
    </link>

    <joint name="ee_bar" type="fixed">
      <axis xyz="1 0 0"/>
      <origin rpy="0 0 0" xyz="0.025875 0 0"/>
      <parent link="gripper_bar_link"/>
      <child link="fingers_link"/>
    </joint>

    <link name="fingers_link">
      <inertial>
        <mass value="0.001" />
        <inertia ixx="0.0001" iyy="0.0001" izz="0.0001" ixy="0" ixz="0" iyz="0" />
      </inertial>
    </link>

    <joint name="left_finger" type="prismatic">
        <axis xyz="0 1 0"/>
        <limit effort="5" lower="0.021" upper="0.057" velocity="1"/>
        <origin rpy="0 0 0" xyz="0 0 0"/>
        <parent link="fingers_link"/>
        <child link="left_finger_link"/>
        <dynamics friction="0.1"/>
    </joint>

    <link name="left_finger_link">
        <visual>
            <origin rpy="1.5708 -3.1416 1.5708" xyz="-0.0404 -0.0575 0"/>
            <geometry>
            <mesh filename="package:///vx300s_10_gripper_finger.stl" scale="0.001 0.001 0.001"/>
            </geometry>
            <material name="interbotix_black"/>
        </visual>
        <collision>
            <origin rpy="1.5708 -3.1416 1.5708" xyz="-0.0404 -0.0575 0"/>
            <geometry>
            <mesh filename="package:///vx300s_10_gripper_finger.stl" scale="0.001 0.001 0.001"/>
            </geometry>
        </collision>
        <inertial>
            <origin rpy="3.1416 3.1416 1.5708" xyz="0.0173440000 -0.0060692000 0.0000000000"/>
            <mass value="0.034796" />
            <inertia ixx="0.0000243300" iyy="0.0000125500" izz="0.0000141700" ixy="-0.0000024004" ixz="0.0000000000" iyz="0.0000000000" />
        </inertial>
    </link>

    <joint name="right_finger" type="prismatic">
        <axis xyz="0 1 0"/>
        <limit effort="5" lower="-0.057" upper="-0.021" velocity="1"/>
        <origin rpy="0 0 0" xyz="0 0 0"/>
        <parent link="fingers_link"/>
        <child link="right_finger_link"/>
        <dynamics friction="0.1"/>
    </joint>

    <link name="right_finger_link">
        <visual>
          <origin rpy="-1.5708 3.1416 -1.5708" xyz="-0.0404 0.0575 0 "/>
          <geometry>
            <mesh filename="package:///vx300s_10_gripper_finger.stl" scale="0.001 0.001 0.001"/>
          </geometry>
          <material name="interbotix_black"/>
        </visual>
        <collision>
          <origin rpy="-1.5708 3.1416 -1.5708" xyz="-0.0404 0.0575 0 "/>
          <geometry>
            <mesh filename="package:///vx300s_10_gripper_finger.stl" scale="0.001 0.001 0.001"/>
          </geometry>
        </collision>
        <inertial>
          <origin rpy="0 3.1416 1.5708" xyz="0.0173440000 0.0060692000  0.0000000000"/>
          <mass value="0.034796" />
          <inertia ixx="0.0000243300" iyy="0.0000125500" izz="0.0000141700" ixy="0.0000024001" ixz="0.0000000000" iyz="0.0000000000" />
        </inertial>
    </link>

    <joint name="ee_gripper" type="fixed">
        <axis xyz="1 0 0"/>
        <origin rpy="0 0 0" xyz="0.0385 0 0"/>
        <parent link="fingers_link"/>
        <child link="ee_gripper_link"/>
    </joint>

    <link name="ee_gripper_link">
        <inertial>
            <mass value="0.001" />
            <inertia ixx="0.0001" iyy="0.0001" izz="0.0001" ixy="0" ixz="0" iyz="0" />
        </inertial>
    </link>

    <joint name="ee_site" type="fixed">
        <axis xyz="1 0 0"/>
        <origin rpy="0 0 0" xyz="0.13 0 -0.003"/>
        <parent link="gripper_link"/>
        <child link="ee_site_link"/>
    </joint>

    <link name="ee_site_link">
        <inertial>
            <mass value="0.001" />
            <inertia ixx="0.0001" iyy="0.0001" izz="0.0001" ixy="0" ixz="0" iyz="0" />
        </inertial>
    </link>

</robot>